2017-12-11 12:07:43,541 - teradata.udaexec - INFO - Initializing UdaExec...
2017-12-11 12:07:43,541 - teradata.udaexec - INFO - Reading config files: ['/etc/udaexec.ini: Not Found', '/home/users/hibellm/udaexec.ini: Found', '/data/RWD_SHARE/MDH/users/hibellm/flask/ruflaskapp/udaexec.ini: Not Found']
2017-12-11 12:07:43,541 - teradata.udaexec - INFO - Found run number file: "/data/RWD_SHARE/MDH/users/hibellm/flask/ruflaskapp/.runNumber"
2017-12-11 12:07:43,541 - teradata.udaexec - INFO - Cleaning up log files older than 90 days.
2017-12-11 12:07:43,541 - teradata.udaexec - INFO - Removed 0 log files.
2017-12-11 12:08:18,614 - teradata.udaexec - INFO - Checkpoint file not found: /data/RWD_SHARE/MDH/users/hibellm/flask/ruflaskapp/HelloWorld.checkpoint
2017-12-11 12:08:18,615 - teradata.udaexec - INFO - No previous checkpoint found, executing from beginning...
2017-12-11 12:08:18,615 - teradata.udaexec - INFO - Execution Details:
/********************************************************************************
 * Application Name: HelloWorld
 *          Version: 1.0
 *       Run Number: 20171211120743-16
 *             Host: rkaustms02
 *         Platform: Linux-3.0.101-0.125.TDC.1.R.0-default-x86_64-with-SuSE-11-x86_64
 *          OS User: hibellm
 *   Python Version: 3.5.1
 *  Python Compiler: GCC 4.4.7 20120313 (Red Hat 4.4.7-1)
 *     Python Build: ('default', 'Jun 15 2016 15:32:45')
 *  UdaExec Version: 15.10.0.16
 *     Program Name: td_python.py
 *      Working Dir: /data/RWD_SHARE/MDH/users/hibellm/flask/ruflaskapp
 *      Git Version: git version 2.10.2
 *     Git Revision: 195a97f
 *        Git Dirty: True [ M README.md, M app.py, M app_tdcon.py, M data.py, M listfiles1.txt, M listfiles2.txt, M osscript.py, M td_python.py, M td_python_connection.py, M templates/about.html, M templates/add_datasource.html, M templates/add_vendor.html, M templates/dashboard.html, M templates/dashboardd.html, M templates/dashboardv.html, M templates/datasource.html, M templates/datasources.html, M templates/edit_datasource.html, M templates/edit_vendor.html, M templates/home.html, M templates/includes/_formhelpers.html, M templates/includes/_messages.html, M templates/includes/_navbar.html, M templates/layout.html, M templates/login.html, M templates/register.html, M templates/roles.html, M templates/ru_datasource.html, M templates/shell.html, M templates/tablesort.js, M templates/vendor.html, M templates/vendors.html, M templates/vendors_tdcon.html,?? .runNumber,?? logs/]
 *          Log Dir: /data/RWD_SHARE/MDH/users/hibellm/flask/ruflaskapp/logs
 *         Log File: /data/RWD_SHARE/MDH/users/hibellm/flask/ruflaskapp/logs/HelloWorld.20171211120743-16.log
 *     Config Files: ['/etc/udaexec.ini: Not Found', '/home/users/hibellm/udaexec.ini: Found', '/data/RWD_SHARE/MDH/users/hibellm/flask/ruflaskapp/udaexec.ini: Not Found']
 *      Query Bands: ApplicationName=HelloWorld;Version=1.0;JobID=20171211120743-16;ClientUser=hibellm;Production=False;udaAppLogFile=/data/RWD_SHARE/MDH/users/hibellm/flask/ruflaskapp/logs/HelloWorld.20171211120743-16.log;gitRevision=195a97f;gitDirty=True;UtilityName=PyTd;UtilityVersion=15.10.0.16
********************************************************************************/
2017-12-11 12:08:18,616 - teradata.udaexec - INFO - Creating connection: {'method': 'odbc', 'username': 'hibellm', 'password': 'XXXXXX', 'system': '${system}'}
2017-12-11 12:08:18,617 - teradata.tdodbc - INFO - Loading ODBC Library: libodbc.so
2017-12-11 12:08:18,863 - teradata.udaexec - ERROR - Unable to create connection: {'method': 'odbc', 'username': 'hibellm', 'password': 'XXXXXX', 'system': '${system}'}
Traceback (most recent call last):
  File "/opt/anaconda3/lib/python3.5/site-packages/teradata-15.10.0.16-py3.5.egg/teradata/udaexec.py", line 181, in connect
    **args))
  File "/opt/anaconda3/lib/python3.5/site-packages/teradata-15.10.0.16-py3.5.egg/teradata/tdodbc.py", line 374, in __init__
    checkStatus(rc, hDbc=self.hDbc, method="SQLDriverConnectW")
  File "/opt/anaconda3/lib/python3.5/site-packages/teradata-15.10.0.16-py3.5.egg/teradata/tdodbc.py", line 206, in checkStatus
    raise DatabaseError(i[2], u"[{}] {}".format(i[0], msg), i[0])
teradata.api.DatabaseError: (113, "[08001] [Teradata][Unix system error]  113 Socket error - The Teradata server can't currently be reached over this network")
2017-12-11 12:08:18,864 - teradata.udaexec - ERROR - Uncaught exception
Traceback (most recent call last):
  File "td_python.py", line 6, in <module>
    session = udaExec.connect(method="odbc", system="$${system}",username="hibellm", password="$$tdwallet(pw_tera)");
  File "/opt/anaconda3/lib/python3.5/site-packages/teradata-15.10.0.16-py3.5.egg/teradata/udaexec.py", line 181, in connect
    **args))
  File "/opt/anaconda3/lib/python3.5/site-packages/teradata-15.10.0.16-py3.5.egg/teradata/tdodbc.py", line 374, in __init__
    checkStatus(rc, hDbc=self.hDbc, method="SQLDriverConnectW")
  File "/opt/anaconda3/lib/python3.5/site-packages/teradata-15.10.0.16-py3.5.egg/teradata/tdodbc.py", line 206, in checkStatus
    raise DatabaseError(i[2], u"[{}] {}".format(i[0], msg), i[0])
teradata.api.DatabaseError: (113, "[08001] [Teradata][Unix system error]  113 Socket error - The Teradata server can't currently be reached over this network")
2017-12-11 12:08:18,865 - teradata.udaexec - INFO - UdaExec exiting.
