2017-12-11 14:48:36,866 - teradata.udaexec - INFO - Initializing UdaExec...
2017-12-11 14:48:36,866 - teradata.udaexec - INFO - Reading config files: ['/etc/udaexec.ini: Not Found', '/home/users/hibellm/udaexec.ini: Found', '/data/RWD_SHARE/MDH/users/hibellm/flask/ruflaskapp/udaexec.ini: Not Found']
2017-12-11 14:48:36,866 - teradata.udaexec - INFO - Found run number file: "/data/RWD_SHARE/MDH/users/hibellm/flask/ruflaskapp/.runNumber"
2017-12-11 14:48:36,866 - teradata.udaexec - INFO - Cleaning up log files older than 90 days.
2017-12-11 14:48:36,866 - teradata.udaexec - INFO - Removed 0 log files.
2017-12-11 14:49:07,944 - teradata.udaexec - ERROR - Uncaught exception
Traceback (most recent call last):
  File "app_tdcon.py", line 14, in <module>
    udaExec = teradata.UdaExec (appName="RU Flaskapp", version="1.0",logConsole=True)
  File "/opt/anaconda3/lib/python3.5/site-packages/teradata-15.10.0.16-py3.5.egg/teradata/udaexec.py", line 128, in __init__
    version, default=""), self.config.resolve(gitPath, default=""))
  File "/opt/anaconda3/lib/python3.5/site-packages/teradata-15.10.0.16-py3.5.egg/teradata/udaexec.py", line 366, in _initVersion
    stderr=subprocess.STDOUT).decode("utf-8").strip()
  File "/opt/anaconda3/lib/python3.5/subprocess.py", line 629, in check_output
    **kwargs).stdout
  File "/opt/anaconda3/lib/python3.5/subprocess.py", line 698, in run
    stdout, stderr = process.communicate(input, timeout=timeout)
  File "/opt/anaconda3/lib/python3.5/subprocess.py", line 1055, in communicate
    stdout = self.stdout.read()
KeyboardInterrupt
