2017-12-11 12:50:04,829 - teradata.udaexec - INFO - Initializing UdaExec...
2017-12-11 12:50:04,829 - teradata.udaexec - INFO - Reading config files: ['/etc/udaexec.ini: Not Found', '/home/users/hibellm/udaexec.ini: Found', '/data/RWD_SHARE/MDH/users/hibellm/flask/ruflaskapp/udaexec.ini: Not Found']
2017-12-11 12:50:04,829 - teradata.udaexec - INFO - Found run number file: "/data/RWD_SHARE/MDH/users/hibellm/flask/ruflaskapp/.runNumber"
2017-12-11 12:50:04,829 - teradata.udaexec - INFO - Cleaning up log files older than 90 days.
2017-12-11 12:50:04,829 - teradata.udaexec - INFO - Removed 0 log files.
2017-12-11 12:50:39,910 - teradata.udaexec - INFO - Checkpoint file not found: /data/RWD_SHARE/MDH/users/hibellm/flask/ruflaskapp/RU Flaskapp.checkpoint
2017-12-11 12:50:39,911 - teradata.udaexec - INFO - No previous checkpoint found, executing from beginning...
2017-12-11 12:50:39,911 - teradata.udaexec - INFO - Execution Details:
/********************************************************************************
 * Application Name: RU Flaskapp
 *          Version: 1.0
 *       Run Number: 20171211125004-17
 *             Host: rkaustms02
 *         Platform: Linux-3.0.101-0.125.TDC.1.R.0-default-x86_64-with-SuSE-11-x86_64
 *          OS User: hibellm
 *   Python Version: 3.5.1
 *  Python Compiler: GCC 4.4.7 20120313 (Red Hat 4.4.7-1)
 *     Python Build: ('default', 'Jun 15 2016 15:32:45')
 *  UdaExec Version: 15.10.0.16
 *     Program Name: app_tdcon.py
 *      Working Dir: /data/RWD_SHARE/MDH/users/hibellm/flask/ruflaskapp
 *      Git Version: git version 2.10.2
 *     Git Revision: 195a97f
 *        Git Dirty: True [ M README.md, M app.py, M app_tdcon.py, M data.py, M listfiles1.txt, M listfiles2.txt, M osscript.py, M td_python.py, M td_python_connection.py, M templates/about.html, M templates/add_datasource.html, M templates/add_vendor.html, M templates/dashboard.html, M templates/dashboardd.html, M templates/dashboardv.html, M templates/datasource.html, M templates/datasources.html, M templates/edit_datasource.html, M templates/edit_vendor.html, M templates/home.html, M templates/includes/_formhelpers.html, M templates/includes/_messages.html, M templates/includes/_navbar.html, M templates/layout.html, M templates/login.html, M templates/register.html, M templates/roles.html, M templates/ru_datasource.html, M templates/shell.html, M templates/tablesort.js, M templates/vendor.html, M templates/vendors.html, M templates/vendors_tdcon.html,?? .runNumber,?? logs/]
 *          Log Dir: /data/RWD_SHARE/MDH/users/hibellm/flask/ruflaskapp/logs
 *         Log File: /data/RWD_SHARE/MDH/users/hibellm/flask/ruflaskapp/logs/RU Flaskapp.20171211125004-17.log
 *     Config Files: ['/etc/udaexec.ini: Not Found', '/home/users/hibellm/udaexec.ini: Found', '/data/RWD_SHARE/MDH/users/hibellm/flask/ruflaskapp/udaexec.ini: Not Found']
 *      Query Bands: ApplicationName=RU Flaskapp;Version=1.0;JobID=20171211125004-17;ClientUser=hibellm;Production=False;udaAppLogFile=/data/RWD_SHARE/MDH/users/hibellm/flask/ruflaskapp/logs/RU Flaskapp.20171211125004-17.log;gitRevision=195a97f;gitDirty=True;UtilityName=PyTd;UtilityVersion=15.10.0.16
********************************************************************************/
2017-12-11 12:50:39,913 - teradata.udaexec - INFO - Creating connection: {'password': 'XXXXXX', 'method': 'odbc', 'system': 'rochetd', 'username': '$tdwallet(username)'}
2017-12-11 12:50:39,913 - teradata.tdodbc - INFO - Loading ODBC Library: libodbc.so
2017-12-11 12:50:40,090 - teradata.udaexec - ERROR - Unable to create connection: {'password': 'XXXXXX', 'method': 'odbc', 'system': 'rochetd', 'username': '$tdwallet(username)'}
Traceback (most recent call last):
  File "/opt/anaconda3/lib/python3.5/site-packages/teradata-15.10.0.16-py3.5.egg/teradata/udaexec.py", line 181, in connect
    **args))
  File "/opt/anaconda3/lib/python3.5/site-packages/teradata-15.10.0.16-py3.5.egg/teradata/tdodbc.py", line 374, in __init__
    checkStatus(rc, hDbc=self.hDbc, method="SQLDriverConnectW")
  File "/opt/anaconda3/lib/python3.5/site-packages/teradata-15.10.0.16-py3.5.egg/teradata/tdodbc.py", line 206, in checkStatus
    raise DatabaseError(i[2], u"[{}] {}".format(i[0], msg), i[0])
teradata.api.DatabaseError: (8017, '[28000] [Teradata][ODBC Teradata Driver][Teradata Database] The UserId, Password or Account is invalid. ')
2017-12-11 12:50:40,092 - teradata.udaexec - ERROR - Uncaught exception
Traceback (most recent call last):
  File "app_tdcon.py", line 15, in <module>
    session = udaExec.connect(method="odbc", system="rochetd",username="$$tdwallet(username)", password="$$tdwallet(pw_tera)");
  File "/opt/anaconda3/lib/python3.5/site-packages/teradata-15.10.0.16-py3.5.egg/teradata/udaexec.py", line 181, in connect
    **args))
  File "/opt/anaconda3/lib/python3.5/site-packages/teradata-15.10.0.16-py3.5.egg/teradata/tdodbc.py", line 374, in __init__
    checkStatus(rc, hDbc=self.hDbc, method="SQLDriverConnectW")
  File "/opt/anaconda3/lib/python3.5/site-packages/teradata-15.10.0.16-py3.5.egg/teradata/tdodbc.py", line 206, in checkStatus
    raise DatabaseError(i[2], u"[{}] {}".format(i[0], msg), i[0])
teradata.api.DatabaseError: (8017, '[28000] [Teradata][ODBC Teradata Driver][Teradata Database] The UserId, Password or Account is invalid. ')
2017-12-11 12:50:40,093 - teradata.udaexec - INFO - UdaExec exiting.
